Workbook

Sheet 貼付
A1: セット組 | B1: セット組作成数 | C1: 割引率 | D1: 割引額 | E1: 商品コード | F1: 仕入先コード | G1: JANコード | H1: ブランド | I1: 商品名 | J1: 規格 | K1: 入り数 | L1: 本体価格 | M1: 税率 | N1: 税込仕入単価 | O1: 運賃 | P1: 税込売価 | Q1: 商品コメント（１言） | R1: 商品コメント（長め） | T1: ヤフオクカテゴリーID | U1: 楽天ディレクトリーID | W1: 項目は今後、増やすのでこの行にデータが入っている場合はマスタに反映 | X1: 項目は今後、増やすのでこの行にデータが入っている場合はマスタに反映 | Y1: 項目は今後、増やすのでこの行にデータが入っている場合はマスタに反映 | Z1: 項目は今後、増やすのでこの行にデータが入っている場合はマスタに反映 | AA1: 項目は今後、増やすのでこの行にデータが入っている場合はマスタに反映 | AB1: 項目は今後、増やすのでこの行にデータが入っている場合はマスタに反映 | AC1: 項目は今後、増やすのでこの行にデータが入っている場合はマスタに反映 | AD1: 項目は今後、増やすのでこの行にデータが入っている場合はマスタに反映 | AE1: 項目は今後、増やすのでこの行にデータが入っている場合はマスタに反映
A2: 個 | B2: 10 | F2: 1000 | G2: 4516552522125 | H2: フェニックス | I2: かもす 温泉豆乳ﾎﾞﾃﾞｨｿｰﾌﾟ 18L | L2: 1000 | M2: 0.1 | N2: =IF(G2>=1,ROUNDUP(L2*M2,0)+L2,"") -> 1100 | O2: 500 | P2: 2000
A3: 個 | B3: 20 | F3: 1000 | G3: 4516552208835 | H3: フェニックス | I3: かもす 温泉豆乳ｼｬﾝﾌﾟｰ 18L | L3: 2000 | M3: 0.1 | N3: =IF(G3>=1,ROUNDUP(L3*M3,0)+L3,"") -> 2200 | O3: 500
A4: セット | B4: 30 | F4: 1000 | G4: 4516552001606 | H4: フェニックス | I4: かもす 温泉豆乳ｺﾝﾃﾞｨｼｮﾅｰ 18L | L4: 3000 | M4: 0.1 | N4: =IF(G4>=1,ROUNDUP(L4*M4,0)+L4,"") -> 3300
B5: 40 | F5: 1000 | G5: 4516552522583 | H5: フェニックス | I5: 花蜜精みつばちﾊﾆｰﾎﾞﾃﾞｨｿｰﾌﾟ 18L | L5: 4000 | M5: 0.1 | N5: =IF(G5>=1,ROUNDUP(L5*M5,0)+L5,"") -> 4400
F6: 1000 | G6: 4516552208162 | H6: フェニックス | I6: 花蜜精みつばちﾊﾆｰﾄﾘｰﾄﾒﾝﾄｼｬﾝﾌﾟｰ 18L | L6: 5000 | M6: 0.1 | N6: =IF(G6>=1,ROUNDUP(L6*M6,0)+L6,"") -> 5500
F7: 1000 | G7: 4516552001552 | H7: フェニックス | I7: 花蜜精みつばちﾊﾆｰﾍｱｺﾝﾃﾞｨｼｮﾅｰ 18L | L7: 6000 | M7: 0.1 | N7: =IF(G7>=1,ROUNDUP(L7*M7,0)+L7,"") -> 6600
F8: 1000 | G8: 4516552503632 | H8: フェニックス | I8: 自然にやさしいﾎﾞﾃﾞｨｿｰﾌﾟ 18L | L8: 7000 | M8: 0.1 | N8: =IF(G8>=1,ROUNDUP(L8*M8,0)+L8,"") -> 7700
F9: 1000 | G9: 4516552504124 | H9: フェニックス | I9: 自然にやさしいﾘﾝｽｲﾝｼｬﾝﾌﾟｰ 18L | L9: 8000 | M9: 0.1 | N9: =IF(G9>=1,ROUNDUP(L9*M9,0)+L9,"") -> 8800
F10: 1000 | G10: 4516552522352 | H10: フェニックス | I10: ﾐｵﾎﾞﾃﾞｨｿｰﾌﾟ 18L×1 | L10: 9000 | M10: 0.1 | N10: =IF(G10>=1,ROUNDUP(L10*M10,0)+L10,"") -> 9900
F11: 1000 | G11: 4516552506455 | H11: フェニックス | I11: ﾐｵﾘﾝｽｲﾝｼｬﾝﾌﾟｰ 18L×1 | L11: 10000 | M11: 0.1 | N11: =IF(G11>=1,ROUNDUP(L11*M11,0)+L11,"") -> 11000
F12: 1000 | G12: 4516552522655 | H12: フェニックス | I12: ﾐｵﾎﾞﾃﾞｨｿｰﾌﾟ 詰替用CBX 1000mL×8本 | L12: 11000 | M12: 0.1 | N12: =IF(G12>=1,ROUNDUP(L12*M12,0)+L12,"") -> 12100
F13: 1000 | G13: 4516552520251 | H13: フェニックス | I13: ﾐｵﾘﾝｽｲﾝｼｬﾝﾌﾟｰ 詰替用CBX 1000mL×8本 | L13: 12000 | M13: 0.1 | N13: =IF(G13>=1,ROUNDUP(L13*M13,0)+L13,"") -> 13200
F14: 1000 | G14: 4516552504415 | H14: フェニックス | I14: ﾊｰﾌﾞﾎﾞﾃﾞｨｿｰﾌﾟ 18L×1 | L14: 13000 | M14: 0.1 | N14: =IF(G14>=1,ROUNDUP(L14*M14,0)+L14,"") -> 14300
F15: 1000 | G15: 4516552505286 | H15: フェニックス | I15: ﾊｰﾌﾞﾘﾝｽｲﾝｼｬﾝﾌﾟｰ 18L×1 | L15: 14000 | M15: 0.1 | N15: =IF(G15>=1,ROUNDUP(L15*M15,0)+L15,"") -> 15400
F16: 1000 | G16: 4516552505452 | H16: フェニックス | I16: ﾊｰﾌﾞﾎﾞﾃﾞｨｿｰﾌﾟ 4L×4本 | L16: 15000 | M16: 0.1 | N16: =IF(G16>=1,ROUNDUP(L16*M16,0)+L16,"") -> 16500
F17: 1000 | G17: 4516552505223 | H17: フェニックス | I17: ﾊｰﾌﾞﾘﾝｽｲﾝｼｬﾝﾌﾟｰ 4L×4本 | L17: 16000 | M17: 0.1 | N17: =IF(G17>=1,ROUNDUP(L17*M17,0)+L17,"") -> 17600
... F111: 1000 | G111: 4516552220244 | H111: フェニックス | I111: ARA!薬用手洗い石けん 100g×60個 | L111: 110000 | M111: 0.1 | N111: =IF(G111>=1,ROUNDUP(L111*M111,0)+L111,"") -> 121000

Sheet マスタ登録抽出
A1: № | B1: 商品コード | C1: 仕入先コード | D1: JANコード | E1: ブランド | F1: 商品名 | G1: 規格 | H1: 入り数 | I1: 本体価格 | J1: 税率 | K1: 税込仕入単価 | L1: 運賃 | M1: 税込売価 | N1: 商品コメント（１言） | O1: 商品コメント（長め） | Q1: ヤフオクカテゴリーID | R1: 楽天ディレクトリーID | T1: 項目は今後、増やすのでこの行にデータが入っている場合はマスタに反映 | U1: 項目は今後、増やすのでこの行にデータが入っている場合はマスタに反映 | V1: 項目は今後、増やすのでこの行にデータが入っている場合はマスタに反映 | W1: 項目は今後、増やすのでこの行にデータが入っている場合はマスタに反映 | X1: 項目は今後、増やすのでこの行にデータが入っている場合はマスタに反映 | Y1: 項目は今後、増やすのでこの行にデータが入っている場合はマスタに反映 | Z1: 項目は今後、増やすのでこの行にデータが入っている場合はマスタに反映 | AA1: 項目は今後、増やすのでこの行にデータが入っている場合はマスタに反映 | AB1: 項目は今後、増やすのでこの行にデータが入っている場合はマスタに反映 | AC1: 個数（今だけ）
A2: -1 | B2: =貼付!$G$2&マスタ登録抽出!A2 -> 4516552522125-1 | C2: =貼付!F2 -> 1000 | D2: =貼付!$G$2 -> 4516552522125 | F2: =貼付!$I$2&" "&マスタ登録抽出!AC2&貼付!$A$2 -> かもす 温泉豆乳ﾎﾞﾃﾞｨｿｰﾌﾟ 18L 1個 | I2: =貼付!$L$2*AC2 -> 1000 | K2: =IF(D2>=1,ROUNDUP(I2*J2,0)+I2,"") -> 1000 | L2: 500 | M2: 2000 | AC2: 1
A3: -2 | B3: =貼付!$G$2&マスタ登録抽出!A3 -> 4516552522125-2 | C3: =貼付!F3 -> 1000 | D3: =貼付!$G$2 -> 4516552522125 | F3: =貼付!$I$2&" "&マスタ登録抽出!AC3&貼付!$A$2 -> かもす 温泉豆乳ﾎﾞﾃﾞｨｿｰﾌﾟ 18L 2個 | I3: =貼付!$L$2*AC3 -> 2000 | K3: =IF(D3>=1,ROUNDUP(I3*J3,0)+I3,"") -> 2000 | L3: 1000 | M3: 3600 | AC3: 2
A4: -3 | B4: =貼付!$G$2&マスタ登録抽出!A4 -> 4516552522125-3 | C4: =貼付!F4 -> 1000 | D4: =貼付!$G$2 -> 4516552522125 | F4: =貼付!$I$2&" "&マスタ登録抽出!AC4&貼付!$A$2 -> かもす 温泉豆乳ﾎﾞﾃﾞｨｿｰﾌﾟ 18L 3個 | I4: =貼付!$L$2*AC4 -> 3000 | K4: =IF(D4>=1,ROUNDUP(I4*J4,0)+I4,"") -> 3000 | L4: 1500 | AC4: 3
A5: -4 | B5: =貼付!$G$2&マスタ登録抽出!A5 -> 4516552522125-4 | C5: =貼付!F5 -> 1000 | D5: =貼付!$G$2 -> 4516552522125 | F5: =貼付!$I$2&" "&マスタ登録抽出!AC5&貼付!$A$2 -> かもす 温泉豆乳ﾎﾞﾃﾞｨｿｰﾌﾟ 18L 4個 | I5: =貼付!$L$2*AC5 -> 4000 | K5: =IF(D5>=1,ROUNDUP(I5*J5,0)+I5,"") -> 4000 | L5: 2000 | AC5: 4
A6: -5 | B6: =貼付!$G$2&マスタ登録抽出!A6 -> 4516552522125-5 | C6: =貼付!F6 -> 1000 | D6: =貼付!$G$2 -> 4516552522125 | F6: =貼付!$I$2&" "&マスタ登録抽出!AC6&貼付!$A$2 -> かもす 温泉豆乳ﾎﾞﾃﾞｨｿｰﾌﾟ 18L 5個 | I6: =貼付!$L$2*AC6 -> 5000 | K6: =IF(D6>=1,ROUNDUP(I6*J6,0)+I6,"") -> 5000 | L6: 2500 | AC6: 5
A7: -6 | B7: =貼付!$G$2&マスタ登録抽出!A7 -> 4516552522125-6 | C7: =貼付!F7 -> 1000 | D7: =貼付!$G$2 -> 4516552522125 | F7: =貼付!$I$2&" "&マスタ登録抽出!AC7&貼付!$A$2 -> かもす 温泉豆乳ﾎﾞﾃﾞｨｿｰﾌﾟ 18L 6個 | I7: =貼付!$L$2*AC7 -> 6000 | K7: =IF(D7>=1,ROUNDUP(I7*J7,0)+I7,"") -> 6000 | L7: 3000 | AC7: 6
A8: -7 | B8: =貼付!$G$2&マスタ登録抽出!A8 -> 4516552522125-7 | C8: =貼付!F8 -> 1000 | D8: =貼付!$G$2 -> 4516552522125 | F8: =貼付!$I$2&" "&マスタ登録抽出!AC8&貼付!$A$2 -> かもす 温泉豆乳ﾎﾞﾃﾞｨｿｰﾌﾟ 18L 7個 | I8: =貼付!$L$2*AC8 -> 7000 | K8: =IF(D8>=1,ROUNDUP(I8*J8,0)+I8,"") -> 7000 | L8: 3500 | AC8: 7
A9: -8 | B9: =貼付!$G$2&マスタ登録抽出!A9 -> 4516552522125-8 | C9: =貼付!F9 -> 1000 | D9: =貼付!$G$2 -> 4516552522125 | F9: =貼付!$I$2&" "&マスタ登録抽出!AC9&貼付!$A$2 -> かもす 温泉豆乳ﾎﾞﾃﾞｨｿｰﾌﾟ 18L 8個 | I9: =貼付!$L$2*AC9 -> 8000 | K9: =IF(D9>=1,ROUNDUP(I9*J9,0)+I9,"") -> 8000 | L9: 4000 | AC9: 8
A10: -9 | B10: =貼付!$G$2&マスタ登録抽出!A10 -> 4516552522125-9 | C10: =貼付!F10 -> 1000 | D10: =貼付!$G$2 -> 4516552522125 | F10: =貼付!$I$2&" "&マスタ登録抽出!AC10&貼付!$A$2 -> かもす 温泉豆乳ﾎﾞﾃﾞｨｿｰﾌﾟ 18L 9個 | I10: =貼付!$L$2*AC10 -> 9000 | K10: =IF(D10>=1,ROUNDUP(I10*J10,0)+I10,"") -> 9000 | L10: 4500 | AC10: 9
A11: -10 | B11: =貼付!$G$2&マスタ登録抽出!A11 -> 4516552522125-10 | C11: =貼付!F11 -> 1000 | D11: =貼付!$G$2 -> 4516552522125 | F11: =貼付!$I$2&" "&マスタ登録抽出!AC11&貼付!$A$2 -> かもす 温泉豆乳ﾎﾞﾃﾞｨｿｰﾌﾟ 18L 10個 | I11: =貼付!$L$2*AC11 -> 10000 | K11: =IF(D11>=1,ROUNDUP(I11*J11,0)+I11,"") -> 10000 | L11: 5000 | AC11: 10
A12: -1 | B12: =貼付!$G$2&マスタ登録抽出!A12 -> 4516552522125-1 | C12: =貼付!F12 -> 1000 | D12: =貼付!$G$3 -> 4516552208835 | F12: =貼付!$I$3&" "&マスタ登録抽出!AC12&貼付!$A$2 -> かもす 温泉豆乳ｼｬﾝﾌﾟｰ 18L 1個 | I12: =貼付!$L$3*AC2 -> 2000 | K12: =IF(D12>=1,ROUNDUP(I12*J12,0)+I12,"") -> 2000 | AC12: 1
A13: -2 | B13: =貼付!$G$2&マスタ登録抽出!A13 -> 4516552522125-2 | C13: =貼付!F13 -> 1000 | D13: =貼付!$G$3 -> 4516552208835 | F13: =貼付!$I$3&" "&マスタ登録抽出!AC13&貼付!$A$2 -> かもす 温泉豆乳ｼｬﾝﾌﾟｰ 18L 2個 | I13: =貼付!$L$3*AC3 -> 4000 | K13: =IF(D13>=1,ROUNDUP(I13*J13,0)+I13,"") -> 4000 | AC13: 2
A14: -3 | B14: =貼付!$G$2&マスタ登録抽出!A14 -> 4516552522125-3 | C14: =貼付!F14 -> 1000 | D14: =貼付!$G$3 -> 4516552208835 | F14: =貼付!$I$3&" "&マスタ登録抽出!AC14&貼付!$A$2 -> かもす 温泉豆乳ｼｬﾝﾌﾟｰ 18L 3個 | I14: =貼付!$L$3*AC4 -> 6000 | K14: =IF(D14>=1,ROUNDUP(I14*J14,0)+I14,"") -> 6000 | AC14: 3
A15: -4 | B15: =貼付!$G$2&マスタ登録抽出!A15 -> 4516552522125-4 | C15: =貼付!F15 -> 1000 | D15: =貼付!$G$3 -> 4516552208835 | F15: =貼付!$I$3&" "&マスタ登録抽出!AC15&貼付!$A$2 -> かもす 温泉豆乳ｼｬﾝﾌﾟｰ 18L 4個 | I15: =貼付!$L$3*AC5 -> 8000 | K15: =IF(D15>=1,ROUNDUP(I15*J15,0)+I15,"") -> 8000 | AC15: 4
A16: -5 | B16: =貼付!$G$2&マスタ登録抽出!A16 -> 4516552522125-5 | C16: =貼付!F16 -> 1000 | D16: =貼付!$G$3 -> 4516552208835 | F16: =貼付!$I$3&" "&マスタ登録抽出!AC16&貼付!$A$2 -> かもす 温泉豆乳ｼｬﾝﾌﾟｰ 18L 5個 | I16: =貼付!$L$3*AC6 -> 10000 | K16: =IF(D16>=1,ROUNDUP(I16*J16,0)+I16,"") -> 10000 | AC16: 5
A17: -6 | B17: =貼付!$G$2&マスタ登録抽出!A17 -> 4516552522125-6 | C17: =貼付!F17 -> 1000 | D17: =貼付!$G$3 -> 4516552208835 | F17: =貼付!$I$3&" "&マスタ登録抽出!AC17&貼付!$A$2 -> かもす 温泉豆乳ｼｬﾝﾌﾟｰ 18L 6個 | I17: =貼付!$L$3*AC7 -> 12000 | K17: =IF(D17>=1,ROUNDUP(I17*J17,0)+I17,"") -> 12000 | AC17: 6
A18: -7 | B18: =貼付!$G$2&マスタ登録抽出!A18 -> 4516552522125-7 | C18: =貼付!F18 -> 1000 | D18: =貼付!$G$3 -> 4516552208835 | F18: =貼付!$I$3&" "&マスタ登録抽出!AC18&貼付!$A$2 -> かもす 温泉豆乳ｼｬﾝﾌﾟｰ 18L 7個 | I18: =貼付!$L$3*AC8 -> 14000 | K18: =IF(D18>=1,ROUNDUP(I18*J18,0)+I18,"") -> 14000 | AC18: 7
A19: -8 | B19: =貼付!$G$2&マスタ登録抽出!A19 -> 4516552522125-8 | C19: =貼付!F19 -> 1000 | D19: =貼付!$G$3 -> 4516552208835 | F19: =貼付!$I$3&" "&マスタ登録抽出!AC19&貼付!$A$2 -> かもす 温泉豆乳ｼｬﾝﾌﾟｰ 18L 8個 | I19: =貼付!$L$3*AC9 -> 16000 | K19: =IF(D19>=1,ROUNDUP(I19*J19,0)+I19,"") -> 16000 | AC19: 8
A20: -9 | B20: =貼付!$G$2&マスタ登録抽出!A20 -> 4516552522125-9 | C20: =貼付!F20 -> 1000 | D20: =貼付!$G$3 -> 4516552208835 | F20: =貼付!$I$3&" "&マスタ登録抽出!AC20&貼付!$A$2 -> かもす 温泉豆乳ｼｬﾝﾌﾟｰ 18L 9個 | I20: =貼付!$L$3*AC10 -> 18000 | K20: =IF(D20>=1,ROUNDUP(I20*J20,0)+I20,"") -> 18000 | AC20: 9
A21: -10 | B21: =貼付!$G$2&マスタ登録抽出!A21 -> 4516552522125-10 | C21: =貼付!F21 -> 1000 | D21: =貼付!$G$3 -> 4516552208835 | F21: =貼付!$I$3&" "&マスタ登録抽出!AC21&貼付!$A$2 -> かもす 温泉豆乳ｼｬﾝﾌﾟｰ 18L 10個 | I21: =貼付!$L$3*AC11 -> 20000 | K21: =IF(D21>=1,ROUNDUP(I21*J21,0)+I21,"") -> 20000 | AC21: 10
A22: -1 | B22: =貼付!$G$2&マスタ登録抽出!A22 -> 4516552522125-1 | C22: =貼付!F22 -> 1000 | D22: =貼付!$G$4 -> 4516552001606 | I22: =貼付!$L$4*AC12 -> 3000 | K22: =IF(D22>=1,ROUNDUP(I22*J22,0)+I22,"") -> 3000 | AC22: 1
A23: -2 | B23: =貼付!$G$2&マスタ登録抽出!A23 -> 4516552522125-2 | C23: =貼付!F23 -> 1000 | D23: =貼付!$G$4 -> 4516552001606 | I23: =貼付!$L$4*AC13 -> 6000 | K23: =IF(D23>=1,ROUNDUP(I23*J23,0)+I23,"") -> 6000 | AC23: 2
A24: -3 | B24: =貼付!$G$2&マスタ登録抽出!A24 -> 4516552522125-3 | C24: =貼付!F24 -> 1000 | D24: =貼付!$G$4 -> 4516552001606 | I24: =貼付!$L$4*AC14 -> 9000 | K24: =IF(D24>=1,ROUNDUP(I24*J24,0)+I24,"") -> 9000 | AC24: 3
A25: -4 | B25: =貼付!$G$2&マスタ登録抽出!A25 -> 4516552522125-4 | C25: =貼付!F25 -> 1000 | D25: =貼付!$G$4 -> 4516552001606 | I25: =貼付!$L$4*AC15 -> 12000 | K25: =IF(D25>=1,ROUNDUP(I25*J25,0)+I25,"") -> 12000 | AC25: 4
A26: -5 | B26: =貼付!$G$2&マスタ登録抽出!A26 -> 4516552522125-5 | C26: =貼付!F26 -> 1000 | D26: =貼付!$G$4 -> 4516552001606 | I26: =貼付!$L$4*AC16 -> 15000 | K26: =IF(D26>=1,ROUNDUP(I26*J26,0)+I26,"") -> 15000 | AC26: 5
A27: -6 | B27: =貼付!$G$2&マスタ登録抽出!A27 -> 4516552522125-6 | C27: =貼付!F27 -> 1000 | D27: =貼付!$G$4 -> 4516552001606 | I27: =貼付!$L$4*AC17 -> 18000 | K27: =IF(D27>=1,ROUNDUP(I27*J27,0)+I27,"") -> 18000 | AC27: 6
A28: -7 | B28: =貼付!$G$2&マスタ登録抽出!A28 -> 4516552522125-7 | C28: =貼付!F28 -> 1000 | D28: =貼付!$G$4 -> 4516552001606 | I28: =貼付!$L$4*AC18 -> 21000 | K28: =IF(D28>=1,ROUNDUP(I28*J28,0)+I28,"") -> 21000 | AC28: 7
A29: -8 | B29: =貼付!$G$2&マスタ登録抽出!A29 -> 4516552522125-8 | C29: =貼付!F29 -> 1000 | D29: =貼付!$G$4 -> 4516552001606 | I29: =貼付!$L$4*AC19 -> 24000 | K29: =IF(D29>=1,ROUNDUP(I29*J29,0)+I29,"") -> 24000 | AC29: 8
A30: -9 | B30: =貼付!$G$2&マスタ登録抽出!A30 -> 4516552522125-9 | C30: =貼付!F30 -> 1000 | D30: =貼付!$G$4 -> 4516552001606 | I30: =貼付!$L$4*AC20 -> 27000 | K30: =IF(D30>=1,ROUNDUP(I30*J30,0)+I30,"") -> 27000 | AC30: 9
A31: -10 | B31: =貼付!$G$2&マスタ登録抽出!A31 -> 4516552522125-10 | C31: =貼付!F31 -> 1000 | D31: =貼付!$G$4 -> 4516552001606 | I31: =貼付!$L$4*AC21 -> 30000 | K31: =IF(D31>=1,ROUNDUP(I31*J31,0)+I31,"") -> 30000 | AC31: 10
A92: -1 | B92: =貼付!$G$2&マスタ登録抽出!A92 -> 4516552522125-1 | K92: =IF(D92>=1,ROUNDUP(I92*J92,0)+I92,"") | AC92: 1
A93: -2 | B93: =貼付!$G$2&マスタ登録抽出!A93 -> 4516552522125-2 | K93: =IF(D93>=1,ROUNDUP(I93*J93,0)+I93,"") | AC93: 2
A94: -3 | B94: =貼付!$G$2&マスタ登録抽出!A94 -> 4516552522125-3 | K94: =IF(D94>=1,ROUNDUP(I94*J94,0)+I94,"") | AC94: 3
A95: -4 | B95: =貼付!$G$2&マスタ登録抽出!A95 -> 4516552522125-4 | K95: =IF(D95>=1,ROUNDUP(I95*J95,0)+I95,"") | AC95: 4
A96: -5 | B96: =貼付!$G$2&マスタ登録抽出!A96 -> 4516552522125-5 | K96: =IF(D96>=1,ROUNDUP(I96*J96,0)+I96,"") | AC96: 5
A97: -6 | B97: =貼付!$G$2&マスタ登録抽出!A97 -> 4516552522125-6 | K97: =IF(D97>=1,ROUNDUP(I97*J97,0)+I97,"") | AC97: 6
A98: -7 | B98: =貼付!$G$2&マスタ登録抽出!A98 -> 4516552522125-7 | K98: =IF(D98>=1,ROUNDUP(I98*J98,0)+I98,"") | AC98: 7
A99: -8 | B99: =貼付!$G$2&マスタ登録抽出!A99 -> 4516552522125-8 | K99: =IF(D99>=1,ROUNDUP(I99*J99,0)+I99,"") | AC99: 8
A100: -9 | B100: =貼付!$G$2&マスタ登録抽出!A100 -> 4516552522125-9 | K100: =IF(D100>=1,ROUNDUP(I100*J100,0)+I100,"") | AC100: 9
...
