Workbook

Sheet 貼付
A1: 商品コード | B1: 仕入先コード | C1: JANコード | D1: ブランド | E1: 商品名 | F1: 規格 | G1: 入り数 | H1: 本体価格 | I1: 税率 | J1: 税込仕入単価 | K1: 運賃 | L1: 税込売価 | M1: 商品コメント（１言） | N1: 商品コメント（長め） | P1: セット組 | Q1: セット組作成数 | R1: オフ率
B2: 1000 | C2: 4516552522125 | D2: フェニックス | E2: かもす 温泉豆乳ﾎﾞﾃﾞｨｿｰﾌﾟ 18L | H2: 1000 | I2: 0.1 | J2: =IF(C2>=1,ROUNDUP(H2*I2,0)+H2,"") -> 1100 | K2: 500 | L2: 2000 | P2: 個 | Q2: 10 | R2: 0.1
B3: 1000 | C3: 4516552208835 | D3: フェニックス | E3: かもす 温泉豆乳ｼｬﾝﾌﾟｰ 18L | H3: 2000 | I3: 0.1 | J3: =IF(C3>=1,ROUNDUP(H3*I3,0)+H3,"") -> 2200 | K3: 500 | P3: 個 | Q3: 20
B4: 1000 | C4: 4516552001606 | D4: フェニックス | E4: かもす 温泉豆乳ｺﾝﾃﾞｨｼｮﾅｰ 18L | H4: 3000 | I4: 0.1 | J4: =IF(C4>=1,ROUNDUP(H4*I4,0)+H4,"") -> 3300 | P4: セット | Q4: 30
B5: 1000 | C5: 4516552522583 | D5: フェニックス | E5: 花蜜精みつばちﾊﾆｰﾎﾞﾃﾞｨｿｰﾌﾟ 18L | H5: 4000 | I5: 0.1 | J5: =IF(C5>=1,ROUNDUP(H5*I5,0)+H5,"") -> 4400 | Q5: 40
B6: 1000 | C6: 4516552208162 | D6: フェニックス | E6: 花蜜精みつばちﾊﾆｰﾄﾘｰﾄﾒﾝﾄｼｬﾝﾌﾟｰ 18L | H6: 5000 | I6: 0.1 | J6: =IF(C6>=1,ROUNDUP(H6*I6,0)+H6,"") -> 5500
B7: 1000 | C7: 4516552001552 | D7: フェニックス | E7: 花蜜精みつばちﾊﾆｰﾍｱｺﾝﾃﾞｨｼｮﾅｰ 18L | H7: 6000 | I7: 0.1 | J7: =IF(C7>=1,ROUNDUP(H7*I7,0)+H7,"") -> 6600
B8: 1000 | C8: 4516552503632 | D8: フェニックス | E8: 自然にやさしいﾎﾞﾃﾞｨｿｰﾌﾟ 18L | H8: 7000 | I8: 0.1 | J8: =IF(C8>=1,ROUNDUP(H8*I8,0)+H8,"") -> 7700
B9: 1000 | C9: 4516552504124 | D9: フェニックス | E9: 自然にやさしいﾘﾝｽｲﾝｼｬﾝﾌﾟｰ 18L | H9: 8000 | I9: 0.1 | J9: =IF(C9>=1,ROUNDUP(H9*I9,0)+H9,"") -> 8800
B10: 1000 | C10: 4516552522352 | D10: フェニックス | E10: ﾐｵﾎﾞﾃﾞｨｿｰﾌﾟ 18L×1 | H10: 9000 | I10: 0.1 | J10: =IF(C10>=1,ROUNDUP(H10*I10,0)+H10,"") -> 9900
B11: 1000 | C11: 4516552506455 | D11: フェニックス | E11: ﾐｵﾘﾝｽｲﾝｼｬﾝﾌﾟｰ 18L×1 | H11: 10000 | I11: 0.1 | J11: =IF(C11>=1,ROUNDUP(H11*I11,0)+H11,"") -> 11000
B12: 1000 | C12: 4516552522655 | D12: フェニックス | E12: ﾐｵﾎﾞﾃﾞｨｿｰﾌﾟ 詰替用CBX 1000mL×8本 | H12: 11000 | I12: 0.1 | J12: =IF(C12>=1,ROUNDUP(H12*I12,0)+H12,"") -> 12100
B13: 1000 | C13: 4516552520251 | D13: フェニックス | E13: ﾐｵﾘﾝｽｲﾝｼｬﾝﾌﾟｰ 詰替用CBX 1000mL×8本 | H13: 12000 | I13: 0.1 | J13: =IF(C13>=1,ROUNDUP(H13*I13,0)+H13,"") -> 13200
B14: 1000 | C14: 4516552504415 | D14: フェニックス | E14: ﾊｰﾌﾞﾎﾞﾃﾞｨｿｰﾌﾟ 18L×1 | H14: 13000 | I14: 0.1 | J14: =IF(C14>=1,ROUNDUP(H14*I14,0)+H14,"") -> 14300
B15: 1000 | C15: 4516552505286 | D15: フェニックス | E15: ﾊｰﾌﾞﾘﾝｽｲﾝｼｬﾝﾌﾟｰ 18L×1 | H15: 14000 | I15: 0.1 | J15: =IF(C15>=1,ROUNDUP(H15*I15,0)+H15,"") -> 15400
B16: 1000 | C16: 4516552505452 | D16: フェニックス | E16: ﾊｰﾌﾞﾎﾞﾃﾞｨｿｰﾌﾟ 4L×4本 | H16: 15000 | I16: 0.1 | J16: =IF(C16>=1,ROUNDUP(H16*I16,0)+H16,"") -> 16500
B17: 1000 | C17: 4516552505223 | D17: フェニックス | E17: ﾊｰﾌﾞﾘﾝｽｲﾝｼｬﾝﾌﾟｰ 4L×4本 | H17: 16000 | I17: 0.1 | J17: =IF(C17>=1,ROUNDUP(H17*I17,0)+H17,"") -> 17600
... B111: 1000 | C111: 4516552220244 | D111: フェニックス | E111: ARA!薬用手洗い石けん 100g×60個 | H111: 110000 | I111: 0.1 | J111: =IF(C111>=1,ROUNDUP(H111*I111,0)+H111,"") -> 121000

Sheet マスタ登録抽出
A1: № | B1: 商品コード | C1: 仕入先コード | D1: JANコード | E1: ブランド | F1: 商品名 | G1: 規格 | H1: 入り数 | I1: 本体価格 | J1: 税率 | K1: 税込仕入単価 | L1: 運賃 | M1: 税込売価 | N1: 商品コメント（１言） | O1: 商品コメント（長め）
A2: -1 | B2: =貼付!$C$2&マスタ登録抽出!A2 -> 4516552522125-1 | C2: =貼付!B2 -> 1000 | D2: =貼付!$C$2 -> 4516552522125 | F2: =貼付!E2&" "&マスタ登録抽出!P2&貼付!$P$2 -> かもす 温泉豆乳ﾎﾞﾃﾞｨｿｰﾌﾟ 18L 1個 | I2: =貼付!$H$2*P2 -> 1000 | K2: =IF(D2>=1,ROUNDUP(I2*J2,0)+I2,"") -> 1000 | L2: 500 | M2: 2000 | P2: 1
A3: -2 | B3: =貼付!$C$2&マスタ登録抽出!A3 -> 4516552522125-2 | C3: =貼付!B3 -> 1000 | D3: =貼付!$C$2 -> 4516552522125 | F3: =貼付!E3&" "&マスタ登録抽出!P3&貼付!$P$2 -> かもす 温泉豆乳ｼｬﾝﾌﾟｰ 18L 2個 | I3: =貼付!$H$2*P3 -> 2000 | K3: =IF(D3>=1,ROUNDUP(I3*J3,0)+I3,"") -> 2000 | L3: 1000 | M3: 3600 | P3: 2
A4: -3 | B4: =貼付!$C$2&マスタ登録抽出!A4 -> 4516552522125-3 | C4: =貼付!B4 -> 1000 | D4: =貼付!$C$2 -> 4516552522125 | F4: =貼付!E4&" "&マスタ登録抽出!P4&貼付!$P$2 -> かもす 温泉豆乳ｺﾝﾃﾞｨｼｮﾅｰ 18L 3個 | I4: =貼付!$H$2*P4 -> 3000 | K4: =IF(D4>=1,ROUNDUP(I4*J4,0)+I4,"") -> 3000 | L4: 1500 | P4: 3
A5: -4 | B5: =貼付!$C$2&マスタ登録抽出!A5 -> 4516552522125-4 | C5: =貼付!B5 -> 1000 | D5: =貼付!$C$2 -> 4516552522125 | F5: =貼付!E5&" "&マスタ登録抽出!P5&貼付!$P$2 -> 花蜜精みつばちﾊﾆｰﾎﾞﾃﾞｨｿｰﾌﾟ 18L 4個 | I5: =貼付!$H$2*P5 -> 4000 | K5: =IF(D5>=1,ROUNDUP(I5*J5,0)+I5,"") -> 4000 | L5: 2000 | P5: 4
A6: -5 | B6: =貼付!$C$2&マスタ登録抽出!A6 -> 4516552522125-5 | C6: =貼付!B6 -> 1000 | D6: =貼付!$C$2 -> 4516552522125 | F6: =貼付!E6&" "&マスタ登録抽出!P6&貼付!$P$2 -> 花蜜精みつばちﾊﾆｰﾄﾘｰﾄﾒﾝﾄｼｬﾝﾌﾟｰ 18L 5個 | I6: =貼付!$H$2*P6 -> 5000 | K6: =IF(D6>=1,ROUNDUP(I6*J6,0)+I6,"") -> 5000 | L6: 2500 | P6: 5
A7: -6 | B7: =貼付!$C$2&マスタ登録抽出!A7 -> 4516552522125-6 | C7: =貼付!B7 -> 1000 | D7: =貼付!$C$2 -> 4516552522125 | F7: =貼付!E7&" "&マスタ登録抽出!P7&貼付!$P$2 -> 花蜜精みつばちﾊﾆｰﾍｱｺﾝﾃﾞｨｼｮﾅｰ 18L 6個 | I7: =貼付!$H$2*P7 -> 6000 | K7: =IF(D7>=1,ROUNDUP(I7*J7,0)+I7,"") -> 6000 | L7: 3000 | P7: 6
A8: -7 | B8: =貼付!$C$2&マスタ登録抽出!A8 -> 4516552522125-7 | C8: =貼付!B8 -> 1000 | D8: =貼付!$C$2 -> 4516552522125 | F8: =貼付!E8&" "&マスタ登録抽出!P8&貼付!$P$2 -> 自然にやさしいﾎﾞﾃﾞｨｿｰﾌﾟ 18L 7個 | I8: =貼付!$H$2*P8 -> 7000 | K8: =IF(D8>=1,ROUNDUP(I8*J8,0)+I8,"") -> 7000 | L8: 3500 | P8: 7
A9: -8 | B9: =貼付!$C$2&マスタ登録抽出!A9 -> 4516552522125-8 | C9: =貼付!B9 -> 1000 | D9: =貼付!$C$2 -> 4516552522125 | F9: =貼付!E9&" "&マスタ登録抽出!P9&貼付!$P$2 -> 自然にやさしいﾘﾝｽｲﾝｼｬﾝﾌﾟｰ 18L 8個 | I9: =貼付!$H$2*P9 -> 8000 | K9: =IF(D9>=1,ROUNDUP(I9*J9,0)+I9,"") -> 8000 | L9: 4000 | P9: 8
A10: -9 | B10: =貼付!$C$2&マスタ登録抽出!A10 -> 4516552522125-9 | C10: =貼付!B10 -> 1000 | D10: =貼付!$C$2 -> 4516552522125 | F10: =貼付!E10&" "&マスタ登録抽出!P10&貼付!$P$2 -> ﾐｵﾎﾞﾃﾞｨｿｰﾌﾟ 18L×1 9個 | I10: =貼付!$H$2*P10 -> 9000 | K10: =IF(D10>=1,ROUNDUP(I10*J10,0)+I10,"") -> 9000 | L10: 4500 | P10: 9
A11: -10 | B11: =貼付!$C$2&マスタ登録抽出!A11 -> 4516552522125-10 | C11: =貼付!B11 -> 1000 | D11: =貼付!$C$2 -> 4516552522125 | F11: =貼付!E11&" "&マスタ登録抽出!P11&貼付!$P$2 -> ﾐｵﾘﾝｽｲﾝｼｬﾝﾌﾟｰ 18L×1 10個 | I11: =貼付!$H$2*P11 -> 10000 | K11: =IF(D11>=1,ROUNDUP(I11*J11,0)+I11,"") -> 10000 | L11: 5000 | P11: 10
A12: -1 | B12: =貼付!$C$2&マスタ登録抽出!A12 -> 4516552522125-1 | C12: =貼付!B12 -> 1000 | D12: =貼付!$C$3 -> 4516552208835 | F12: =貼付!E12&" "&マスタ登録抽出!P12&貼付!$P$3 -> ﾐｵﾎﾞﾃﾞｨｿｰﾌﾟ 詰替用CBX 1000mL×8本 1個 | I12: =貼付!$H$3*P2 -> 2000 | K12: =IF(D12>=1,ROUNDUP(I12*J12,0)+I12,"") -> 2000 | P12: 1
A13: -2 | B13: =貼付!$C$2&マスタ登録抽出!A13 -> 4516552522125-2 | C13: =貼付!B13 -> 1000 | D13: =貼付!$C$3 -> 4516552208835 | F13: =貼付!E13&" "&マスタ登録抽出!P13&貼付!$P$3 -> ﾐｵﾘﾝｽｲﾝｼｬﾝﾌﾟｰ 詰替用CBX 1000mL×8本 2個 | I13: =貼付!$H$3*P3 -> 4000 | K13: =IF(D13>=1,ROUNDUP(I13*J13,0)+I13,"") -> 4000 | P13: 2
A14: -3 | B14: =貼付!$C$2&マスタ登録抽出!A14 -> 4516552522125-3 | C14: =貼付!B14 -> 1000 | D14: =貼付!$C$3 -> 4516552208835 | F14: =貼付!E14&" "&マスタ登録抽出!P14&貼付!$P$3 -> ﾊｰﾌﾞﾎﾞﾃﾞｨｿｰﾌﾟ 18L×1 3個 | I14: =貼付!$H$3*P4 -> 6000 | K14: =IF(D14>=1,ROUNDUP(I14*J14,0)+I14,"") -> 6000 | P14: 3
A15: -4 | B15: =貼付!$C$2&マスタ登録抽出!A15 -> 4516552522125-4 | C15: =貼付!B15 -> 1000 | D15: =貼付!$C$3 -> 4516552208835 | F15: =貼付!E15&" "&マスタ登録抽出!P15&貼付!$P$3 -> ﾊｰﾌﾞﾘﾝｽｲﾝｼｬﾝﾌﾟｰ 18L×1 4個 | I15: =貼付!$H$3*P5 -> 8000 | K15: =IF(D15>=1,ROUNDUP(I15*J15,0)+I15,"") -> 8000 | P15: 4
A16: -5 | B16: =貼付!$C$2&マスタ登録抽出!A16 -> 4516552522125-5 | C16: =貼付!B16 -> 1000 | D16: =貼付!$C$3 -> 4516552208835 | F16: =貼付!E16&" "&マスタ登録抽出!P16&貼付!$P$3 -> ﾊｰﾌﾞﾎﾞﾃﾞｨｿｰﾌﾟ 4L×4本 5個 | I16: =貼付!$H$3*P6 -> 10000 | K16: =IF(D16>=1,ROUNDUP(I16*J16,0)+I16,"") -> 10000 | P16: 5
A17: -6 | B17: =貼付!$C$2&マスタ登録抽出!A17 -> 4516552522125-6 | C17: =貼付!B17 -> 1000 | D17: =貼付!$C$3 -> 4516552208835 | F17: =貼付!E17&" "&マスタ登録抽出!P17&貼付!$P$3 -> ﾊｰﾌﾞﾘﾝｽｲﾝｼｬﾝﾌﾟｰ 4L×4本 6個 | I17: =貼付!$H$3*P7 -> 12000 | K17: =IF(D17>=1,ROUNDUP(I17*J17,0)+I17,"") -> 12000 | P17: 6
A18: -7 | B18: =貼付!$C$2&マスタ登録抽出!A18 -> 4516552522125-7 | C18: =貼付!B18 -> 1000 | D18: =貼付!$C$3 -> 4516552208835 | F18: =貼付!E18&" "&マスタ登録抽出!P18&貼付!$P$3 -> ﾊｰﾌﾞﾎﾞﾃﾞｨｿｰﾌﾟ 1000mL×12本 7個 | I18: =貼付!$H$3*P8 -> 14000 | K18: =IF(D18>=1,ROUNDUP(I18*J18,0)+I18,"") -> 14000 | P18: 7
A19: -8 | B19: =貼付!$C$2&マスタ登録抽出!A19 -> 4516552522125-8 | C19: =貼付!B19 -> 1000 | D19: =貼付!$C$3 -> 4516552208835 | F19: =貼付!E19&" "&マスタ登録抽出!P19&貼付!$P$3 -> ﾊｰﾌﾞﾘﾝｽｲﾝｼｬﾝﾌﾟｰ 1000mL×12本 8個 | I19: =貼付!$H$3*P9 -> 16000 | K19: =IF(D19>=1,ROUNDUP(I19*J19,0)+I19,"") -> 16000 | P19: 8
A20: -9 | B20: =貼付!$C$2&マスタ登録抽出!A20 -> 4516552522125-9 | C20: =貼付!B20 -> 1000 | D20: =貼付!$C$3 -> 4516552208835 | F20: =貼付!E20&" "&マスタ登録抽出!P20&貼付!$P$3 -> やさしいﾎﾞﾃﾞｨｿｰﾌﾟ 18L×1 9個 | I20: =貼付!$H$3*P10 -> 18000 | K20: =IF(D20>=1,ROUNDUP(I20*J20,0)+I20,"") -> 18000 | P20: 9
A21: -10 | B21: =貼付!$C$2&マスタ登録抽出!A21 -> 4516552522125-10 | C21: =貼付!B21 -> 1000 | D21: =貼付!$C$3 -> 4516552208835 | F21: =貼付!E21&" "&マスタ登録抽出!P21&貼付!$P$3 -> やさしいﾘﾝｽｲﾝｼｬﾝﾌﾟｰ 18L×1 10個 | I21: =貼付!$H$3*P11 -> 20000 | K21: =IF(D21>=1,ROUNDUP(I21*J21,0)+I21,"") -> 20000 | P21: 10
A22: -1 | B22: =貼付!$C$2&マスタ登録抽出!A22 -> 4516552522125-1 | C22: =貼付!B22 -> 1000 | D22: =貼付!$C$4 -> 4516552001606 | F22: =貼付!E22&" "&マスタ登録抽出!P22&貼付!$P$4 -> やさしいﾍｱｼｬﾝﾌﾟｰ 18L×1 1セット | I22: =貼付!$H$4*P12 -> 3000 | K22: =IF(D22>=1,ROUNDUP(I22*J22,0)+I22,"") -> 3000 | P22: 1
A23: -2 | B23: =貼付!$C$2&マスタ登録抽出!A23 -> 4516552522125-2 | C23: =貼付!B23 -> 1000 | D23: =貼付!$C$4 -> 4516552001606 | F23: =貼付!E23&" "&マスタ登録抽出!P23&貼付!$P$4 -> やさしいﾍｱﾘﾝｽ 18L×1 2セット | I23: =貼付!$H$4*P13 -> 6000 | K23: =IF(D23>=1,ROUNDUP(I23*J23,0)+I23,"") -> 6000 | P23: 2
A24: -3 | B24: =貼付!$C$2&マスタ登録抽出!A24 -> 4516552522125-3 | C24: =貼付!B24 -> 1000 | D24: =貼付!$C$4 -> 4516552001606 | F24: =貼付!E24&" "&マスタ登録抽出!P24&貼付!$P$4 -> 馬油さくらﾎﾞﾃﾞｨｿｰﾌﾟ 18L×1 3セット | I24: =貼付!$H$4*P14 -> 9000 | K24: =IF(D24>=1,ROUNDUP(I24*J24,0)+I24,"") -> 9000 | P24: 3
A25: -4 | B25: =貼付!$C$2&マスタ登録抽出!A25 -> 4516552522125-4 | C25: =貼付!B25 -> 1000 | D25: =貼付!$C$4 -> 4516552001606 | F25: =貼付!E25&" "&マスタ登録抽出!P25&貼付!$P$4 -> 馬油さくらｼｬﾝﾌﾟｰ 18L×1 4セット | I25: =貼付!$H$4*P15 -> 12000 | K25: =IF(D25>=1,ROUNDUP(I25*J25,0)+I25,"") -> 12000 | P25: 4
A26: -5 | B26: =貼付!$C$2&マスタ登録抽出!A26 -> 4516552522125-5 | C26: =貼付!B26 -> 1000 | D26: =貼付!$C$4 -> 4516552001606 | F26: =貼付!E26&" "&マスタ登録抽出!P26&貼付!$P$4 -> 馬油さくらｺﾝﾃﾞｨｼｮﾅｰ 18L×1 5セット | I26: =貼付!$H$4*P16 -> 15000 | K26: =IF(D26>=1,ROUNDUP(I26*J26,0)+I26,"") -> 15000 | P26: 5
A27: -6 | B27: =貼付!$C$2&マスタ登録抽出!A27 -> 4516552522125-6 | C27: =貼付!B27 -> 1000 | D27: =貼付!$C$4 -> 4516552001606 | F27: =貼付!E27&" "&マスタ登録抽出!P27&貼付!$P$4 -> 業務用入浴剤｢ﾕｽﾞ｣15kg(7.5kg×2) 7.5kg×2×1 6セット | I27: =貼付!$H$4*P17 -> 18000 | K27: =IF(D27>=1,ROUNDUP(I27*J27,0)+I27,"") -> 18000 | P27: 6
A28: -7 | B28: =貼付!$C$2&マスタ登録抽出!A28 -> 4516552522125-7 | C28: =貼付!B28 -> 1000 | D28: =貼付!$C$4 -> 4516552001606 | F28: =貼付!E28&" "&マスタ登録抽出!P28&貼付!$P$4 -> 業務用入浴剤｢ｻｸﾗ｣15kg(7.5kg×2) 7.5kg×2×1 7セット | I28: =貼付!$H$4*P18 -> 21000 | K28: =IF(D28>=1,ROUNDUP(I28*J28,0)+I28,"") -> 21000 | P28: 7
A29: -8 | B29: =貼付!$C$2&マスタ登録抽出!A29 -> 4516552522125-8 | C29: =貼付!B29 -> 1000 | D29: =貼付!$C$4 -> 4516552001606 | F29: =貼付!E29&" "&マスタ登録抽出!P29&貼付!$P$4 -> 業務用入浴剤｢ﾖﾓｷﾞ｣15kg(7.5kg×2) 7.5kg×2×1 8セット | I29: =貼付!$H$4*P19 -> 24000 | K29: =IF(D29>=1,ROUNDUP(I29*J29,0)+I29,"") -> 24000 | P29: 8
A30: -9 | B30: =貼付!$C$2&マスタ登録抽出!A30 -> 4516552522125-9 | C30: =貼付!B30 -> 1000 | D30: =貼付!$C$4 -> 4516552001606 | F30: =貼付!E30&" "&マスタ登録抽出!P30&貼付!$P$4 -> 業務用入浴剤｢ﾛｰｽﾞ｣15kg(7.5kg×2) 7.5kg×2×1 9セット | I30: =貼付!$H$4*P20 -> 27000 | K30: =IF(D30>=1,ROUNDUP(I30*J30,0)+I30,"") -> 27000 | P30: 9
A31: -10 | B31: =貼付!$C$2&マスタ登録抽出!A31 -> 4516552522125-10 | C31: =貼付!B31 -> 1000 | D31: =貼付!$C$4 -> 4516552001606 | F31: =貼付!E31&" "&マスタ登録抽出!P31&貼付!$P$4 -> 業務用入浴剤｢ﾐﾝﾄ｣15kg(7.5kg×2) 7.5kg×2×1 10セット | I31: =貼付!$H$4*P21 -> 30000 | K31: =IF(D31>=1,ROUNDUP(I31*J31,0)+I31,"") -> 30000 | P31: 10
A92: -1 | B92: =貼付!$C$2&マスタ登録抽出!A92 -> 4516552522125-1 | K92: =IF(D92>=1,ROUNDUP(I92*J92,0)+I92,"") | P92: 1
A93: -2 | B93: =貼付!$C$2&マスタ登録抽出!A93 -> 4516552522125-2 | K93: =IF(D93>=1,ROUNDUP(I93*J93,0)+I93,"") | P93: 2
A94: -3 | B94: =貼付!$C$2&マスタ登録抽出!A94 -> 4516552522125-3 | K94: =IF(D94>=1,ROUNDUP(I94*J94,0)+I94,"") | P94: 3
A95: -4 | B95: =貼付!$C$2&マスタ登録抽出!A95 -> 4516552522125-4 | K95: =IF(D95>=1,ROUNDUP(I95*J95,0)+I95,"") | P95: 4
A96: -5 | B96: =貼付!$C$2&マスタ登録抽出!A96 -> 4516552522125-5 | K96: =IF(D96>=1,ROUNDUP(I96*J96,0)+I96,"") | P96: 5
A97: -6 | B97: =貼付!$C$2&マスタ登録抽出!A97 -> 4516552522125-6 | K97: =IF(D97>=1,ROUNDUP(I97*J97,0)+I97,"") | P97: 6
A98: -7 | B98: =貼付!$C$2&マスタ登録抽出!A98 -> 4516552522125-7 | K98: =IF(D98>=1,ROUNDUP(I98*J98,0)+I98,"") | P98: 7
A99: -8 | B99: =貼付!$C$2&マスタ登録抽出!A99 -> 4516552522125-8 | K99: =IF(D99>=1,ROUNDUP(I99*J99,0)+I99,"") | P99: 8
A100: -9 | B100: =貼付!$C$2&マスタ登録抽出!A100 -> 4516552522125-9 | K100: =IF(D100>=1,ROUNDUP(I100*J100,0)+I100,"") | P100: 9
...
